<?xml version="1.0"?>

<robot name="jetPR">

  <link name="base_link">
    <visual>
      <origin rpy="1.5707963 0 -1.5707963" xyz="0.3725 0.19 -0.25"/>
      <geometry>
        <mesh filename="package://jetPR_description/meshes/chassisv2.STL"  scale="0.001 0.001 0.001"/>
      </geometry>
    </visual>
  </link>
  
  <link name="left_wheel">
    <visual>
      <origin rpy="1.5707963 0 0" xyz="-0.05 0.0 -0.05"/>
      <geometry>
        <mesh filename="package://jetPR_description/meshes/wheel.STL"  scale="0.001 0.001 0.001"/>
      </geometry>
    </visual>
  </link>
  
  <link name="right_wheel">
    <visual>
      <origin rpy="1.5707963 0 3.141592" xyz="0.05 0.0 -0.05"/>
      <geometry>
        <mesh filename="package://jetPR_description/meshes/wheel.STL"  scale="0.001 0.001 0.001"/>
      </geometry>
    </visual>
  </link>
  
  <link name="camera_base_link">
  </link>
  
  <joint name="left" type="continuous">
    <parent link="base_link"/>
    <child link="left_wheel"/>
    <origin xyz="0 0.15 0.05" rpy="0 0 0" />
    <axis xyz="0.0 1.0 0" />
  </joint>
  
  <joint name="right" type="continuous">
    <parent link="base_link"/>
    <child link="right_wheel"/>
    <origin xyz="0 -0.15 0.05" rpy="0 0 0" />
    <axis xyz="0.0 1.0 0" />
  </joint>
  
  <joint name="camera_base_joint" type="continuous">
    <parent link="base_link"/>
    <child link="camera_base_link"/>
    <origin xyz="0.035 0 0.285" rpy="0 0 0" />
    <axis xyz="0.0 1.0 0" />
  </joint>
  
  
</robot>
