<?xml version="1.0"?>

<robot name="jetPR">

  <link name="base_link">
      
    <collision>
      <origin rpy="1.5707963 0 -1.5707963" xyz="0.3725 0.19 -0.25"/>
      <geometry>
        <mesh filename="package://jetPR_description/meshes/chassisv2.STL"  scale="0.001 0.001 0.001"/>
      </geometry>
    </collision>
    
    <inertial>
      <origin xyz="0 0 1" rpy="0 0 0"/>
      <mass value="5"/>
      <inertia
        ixx="1.0" ixy="0.0" ixz="0.0"
        iyy="1.0" iyz="0.0"
        izz="1.0"/>
    </inertial>
    
    <visual>
      <origin rpy="1.5707963 0 -1.5707963" xyz="0.3725 0.19 -0.25"/>
      <geometry>
        <mesh filename="package://jetPR_description/meshes/chassisv2.STL"  scale="0.001 0.001 0.001"/>
      </geometry>
    </visual>
    <collision name='caster_collision'>
      <origin xyz="-0.10 0 0.005" rpy=" 0 0 0"/>
      <geometry>
        <sphere radius="0.005"/>
      </geometry>
      <surface>
        <friction>
          <ode>
            <mu>0</mu>
            <mu2>0</mu2>
            <slip1>1.0</slip1>
            <slip2>1.0</slip2>
          </ode>
        </friction>
      </surface>
    </collision>

    <visual name='caster_visual'>
      <origin xyz="-0.10 0 0.005" rpy=" 0 0 0"/>
      <geometry>
        <sphere radius="0.005"/>
      </geometry>
    </visual>

    <collision name='caster_front_collision'>
      <origin xyz="0.10 0 0.005" rpy=" 0 0 0"/>
      <geometry>
        <sphere radius="0.005"/>
      </geometry>
      <surface>
        <friction>
          <ode>
            <mu>0</mu>
            <mu2>0</mu2>
            <slip1>1.0</slip1>
            <slip2>1.0</slip2>
          </ode>
        </friction>
      </surface>
    </collision>

    <visual name='caster_front_visual'>
      <origin xyz="0.10 0 0.005" rpy=" 0 0 0"/>
      <geometry>
        <sphere radius="0.005"/>
      </geometry>
    </visual>

  </link>
  
  <link name="left_wheel">
    <collision>
      <origin rpy="1.5707963 0 0" xyz="-0.05 0.0 -0.05"/>
      <geometry>
        <mesh filename="package://jetPR_description/meshes/wheel.STL"  scale="0.001 0.001 0.001"/>
      </geometry>
    </collision>
    
    <inertial>
      <origin rpy="1.5707963 0 0" xyz="-0.05 0.0 -0.05"/>
      <mass value="0.3"/>
      <inertia
        ixx="1.0" ixy="0.0" ixz="0.0"
        iyy="1.0" iyz="0.0"
        izz="1.0"/>
    </inertial>
    
    <visual>
      <origin rpy="1.5707963 0 0" xyz="-0.05 0.0 -0.05"/>
      <geometry>
        <mesh filename="package://jetPR_description/meshes/wheel.STL"  scale="0.001 0.001 0.001"/>
      </geometry>
    </visual>
  </link>
  
  <link name="right_wheel">
      
    <collision>
      <origin rpy="1.5707963 0 3.141592" xyz="0.05 0.0 -0.05"/>
      <geometry>
        <mesh filename="package://jetPR_description/meshes/wheel.STL"  scale="0.001 0.001 0.001"/>
      </geometry>
    </collision>
    
    <inertial>
      <origin rpy="1.5707963 0 3.141592" xyz="0.05 0.0 -0.05"/>
      <mass value="0.3"/>
      <inertia
        ixx="1.0" ixy="0.0" ixz="0.0"
        iyy="1.0" iyz="0.0"
        izz="1.0"/>
    </inertial>
    
    <visual>
      <origin rpy="1.5707963 0 3.141592" xyz="0.05 0.0 -0.05"/>
      <geometry>
        <mesh filename="package://jetPR_description/meshes/wheel.STL"  scale="0.001 0.001 0.001"/>
      </geometry>
    </visual>
  </link>
  
  <link name="camera_base_link">
  </link>
  
  <joint name="left" type="continuous">
    <parent link="base_link"/>
    <child link="left_wheel"/>
    <origin xyz="0 0.15 0.05" rpy="0 0 0" />
    <axis xyz="0.0 1.0 0" />
  </joint>
  
  <joint name="right" type="continuous">
    <parent link="base_link"/>
    <child link="right_wheel"/>
    <origin xyz="0 -0.15 0.05" rpy="0 0 0" />
    <axis xyz="0.0 1.0 0" />
  </joint>
  
  <joint name="camera_base_joint" type="continuous">
    <parent link="base_link"/>
    <child link="camera_base_link"/>
    <origin xyz="0.035 0 0.285" rpy="0 0 0" />
    <axis xyz="0.0 1.0 0" />
  </joint>
  
  
</robot>
