<?xml version="1.0"?>

<robot name="jetPR">

  <link name="base_link">
    <visual>
      <origin rpy="1.5707963 0 -1.5707963" xyz="0.3725 0.19 -0.25"/>
      <geometry>
        <mesh filename="package://jetPR_description/meshes/chassisv2.STL"  scale="0.001 0.001 0.001"/>
      </geometry>
    </visual>
    <collision>
      <origin rpy="1.5707963 0 -1.5707963" xyz="0.3725 0.19 -0.25"/>
      <geometry>
        <mesh filename="package://jetPR_description/meshes/chassisv2.STL"  scale="0.001 0.001 0.001"/>
      </geometry>
    </collision>
    <inertial>
      <mass value="5"/>
      <inertia ixx="0.654" ixy="-0.000192" ixz="0.000351" iyy="1.0023" iyz="-0.043" izz="0.947"/>
    </inertial>
    <collision name='caster_collision'>
      <origin xyz="-0.10 0 0.0055" rpy=" 0 0 0"/>
      <geometry>
        <sphere radius="0.005"/>
      </geometry>
      <surface>
        <friction>
          <ode>
            <mu>0</mu>
            <mu2>0</mu2>
            <slip1>0.0</slip1>
            <slip2>0.0</slip2>
          </ode>
        </friction>
      </surface>
    </collision>

    <visual name='caster_visual'>
      <origin xyz="-0.10 0 0.005" rpy=" 0 0 0"/>
      <geometry>
        <sphere radius="0.005"/>
      </geometry>
    </visual>

    <collision name='caster_front_collision'>
      <origin xyz="0.10 0 0.0055" rpy=" 0 0 0"/>
      <geometry>
        <sphere radius="0.005"/>
      </geometry>
      <surface>
        <friction>
          <ode>
            <mu>0</mu>
            <mu2>0</mu2>
            <slip1>0.0</slip1>
            <slip2>0.0</slip2>
          </ode>
        </friction>
      </surface>
    </collision>

    <visual name='caster_front_visual'>
      <origin xyz="0.10 0 0.005" rpy=" 0 0 0"/>
      <geometry>
        <sphere radius="0.005"/>
      </geometry>
    </visual>
  </link>
  
  <link name="left_wheel">
    <visual>
      <origin rpy="1.5707963 0 0" xyz="-0.05 0.0 -0.05"/>
      <geometry>
        <mesh filename="package://jetPR_description/meshes/wheel.STL"  scale="0.001 0.001 0.001"/>
      </geometry>
    </visual>
    <collision>
      <origin rpy="1.5707963 0 0" xyz="-0.05 0.0 -0.05"/>
      <geometry>
        <mesh filename="package://jetPR_description/meshes/wheel.STL"  scale="0.001 0.001 0.001"/>
      </geometry>
    </collision>
    <inertial>
      <mass value="0.5"/>
      <inertia ixx="0.003345" ixy="-2.15e-10" ixz="-7.07e-10" iyy="0.003345" iyz="-2.02e-11" izz="0.0061169"/>
    </inertial>
  </link>
  
  <link name="right_wheel">
    <visual>
      <origin rpy="1.5707963 0 3.141592" xyz="0.05 0.0 -0.05"/>
      <geometry>
        <mesh filename="package://jetPR_description/meshes/wheel.STL"  scale="0.001 0.001 0.001"/>
      </geometry>
    </visual>
    <collision>
      <origin rpy="1.5707963 0 3.141592" xyz="0.05 0.0 -0.05"/>
      <geometry>
        <mesh filename="package://jetPR_description/meshes/wheel.STL"  scale="0.001 0.001 0.001"/>
      </geometry>
    </collision>
    <inertial>
      <mass value="0.5"/>
      <inertia ixx="0.003345" ixy="-2.15e-10" ixz="-7.07e-10" iyy="0.003345" iyz="-2.02e-11" izz="0.0061169"/>
    </inertial>
  </link>
  
  <link name="camera_link">
    <visual>
      <geometry>
        <mesh filename="package://jetPR_description/meshes/kinect.dae" scale="0.0005 0.0005 0.0005"/>
      </geometry>
    </visual>
    <collision>
      <geometry>
        <sphere radius="0.005"/>
        <surface>
        <friction>
          <ode>
            <mu>0</mu>
            <mu2>0</mu2>
            <slip1>0.0</slip1>
            <slip2>0.0</slip2>
          </ode>
        </friction>
      </surface>
      </geometry>
    </collision>
    <inertial>
      <mass value="1e-5" />
      <inertia ixx="1e-5" ixy="0" ixz="0" iyy="1e-5" iyz="0" izz="1e-5" />
    </inertial>
  </link>
    
  <joint name="camera_base_joint" type="continuous">
    <parent link="base_link"/>
    <child link="camera_link"/>
    <origin xyz="0.035 0 0.285" rpy="0 0 0" />
    <axis xyz="0.0 1.0 0" />
  </joint>
  

<transmission name="tran_camera_base_joint">
  <type>transmission_interface/SimpleTransmission</type>
  <joint name="camera_base_joint">
    <hardwareInterface>hardware_interface/PositionJointInterface</hardwareInterface>
  </joint>
  <actuator name="motor_camera_base_joints">
    <mechanicalReduction>1</mechanicalReduction>
  </actuator>
</transmission>

  <gazebo>
  <plugin name="gazebo_ros_control" filename="libgazebo_ros_control.so">
  </plugin>
</gazebo>


  <joint name="left" type="continuous">
    <parent link="base_link"/>
    <child link="left_wheel"/>
    <origin xyz="0 0.15 0.05" rpy="0 0 0" />
    <axis xyz="0.0 1.0 0" />
  </joint>
  
  <joint name="right" type="continuous">
    <parent link="base_link"/>
    <child link="right_wheel"/>
    <origin xyz="0 -0.15 0.05" rpy="0 0 0" />
    <axis xyz="0.0 1.0 0" />
  </joint>
  

      <gazebo>
		<plugin filename="libgazebo_ros_diff_drive.so" name="diff_drive_control">
			<alwaysOn>true</alwaysOn>
			<updateRate>20</updateRate>
			<leftJoint>left</leftJoint>
			<rightJoint>right</rightJoint>
			<wheelSeparation>0.36</wheelSeparation>
			<wheelDiameter>0.1</wheelDiameter>
			<commandTopic>cmd_vel</commandTopic>
			<odometryTopic>odom</odometryTopic>
			<odometryFrame>odom</odometryFrame>
			<robotBaseFrame>base_link</robotBaseFrame>
		</plugin>
	</gazebo>
    
  <gazebo reference="camera_link">
        <sensor type="depth" name="camera">
          <update_rate>20</update_rate>
          <camera>
            <horizontal_fov>1.047198</horizontal_fov>
            <image>
              <format>R8G8B8</format>
              <width>640</width>
              <height>480</height>
            </image>
            <clip>
              <near>0.05</near>
              <far>10</far>
            </clip>
          </camera>
          <plugin name="camera_camera_controller" filename="libgazebo_ros_openni_kinect.so">
            <alwaysOn>true</alwaysOn>
            <updateRate>20</updateRate>
            <imageTopicName>camera/rgb/image_raw</imageTopicName>
            <cameraInfoTopicName>camera/rgb/camera_info</cameraInfoTopicName>
            <depthImageTopicName>camera/depth/image_raw</depthImageTopicName>
            <depthImageCameraInfoTopicName>camera/depth/camera_info</depthImageCameraInfoTopicName>
            <pointCloudTopicName>camera/depth/points</pointCloudTopicName>
            <frameName>camera_link</frameName>
            <distortion_k1>0.0</distortion_k1>
            <distortion_k2>0.0</distortion_k2>
            <distortion_k3>0.0</distortion_k3>
            <distortion_t1>0.0</distortion_t1>
            <distortion_t2>0.0</distortion_t2>
          </plugin>
        </sensor>
      </gazebo>
  
</robot>
